Workbook

Sheet Cover
A1: Trimble Inc. (TRMB)
A2: Three-statement model · scenario analysis · DCF valuation
A4: Selected scenario | B4: =Scenarios!D5
A5: Share price | B5: =DCF!C5
A6: Price date | B6: =DCF!C6
A7: Value per share, selected scenario (blend) | B7: =DCF!C56
A8: Value per share, probability-weighted | B8: =Scenarios!F24
A9: Upside / (downside), probability-weighted | B9: =Scenarios!F25
A10: WACC | B10: =DCF!C24
A12: Balance sheet balances in every year | B12: =IF(SUMPRODUCT(ABS('Balance Sheet'!C27:I27))<0.01,"Yes","NO — check the Balance Sheet")
A13: Cash stays positive in every year | B13: =IF(MIN('Balance Sheet'!E28:I28)=1,"Yes","NO — reduce buybacks or add debt")
A15: Historical years | B15: FY2024A – FY2025A (10-K XBRL)
A16: Projection years | B16: FY2026E – FY2030E
A17: Units | B17: $ millions except per-share
A18: Source | B18: Trimble 10-K FY2024 and FY2025 and Q4 earnings releases, collected via web search (test run; SEC API blocked in this environment)
A19: Colour code | B19: Blue = hard-coded input · Black = formula · Green = link to another sheet · Yellow fill = input cell
A20: How to use | B20: Switch scenarios on the Scenarios sheet (cell C5). Edit yellow cells on Scenarios, Assumptions and DCF.
A21: Method notes | B21: Condensed balance sheet with 'other' lines plugged to reported totals. Interest on opening balances (no circularity). Buybacks retire shares at the current price grown at the cost of equity. Stock comp treated as a cash cost in the DCF.

Sheet Scenarios
A1: Scenarios
A2: Pick a scenario and every sheet (statements, ratios, DCF) recalculates for it.
A5: Selected scenario (1 = Bear, 2 = Base, 3 = Bull) | C5: 2 | D5: =CHOOSE(C5,"Bear","Base","Bull")
A7: Scenario settings | C7: Bear | D7: Base | E7: Bull | G7: Selected
A8: Probability | C8: 0.25 | D8: 0.5 | E8: 0.25 | G8: =CHOOSE($C$5,C8,D8,E8)
A9: Terminal growth | C9: 0.02 | D9: 0.0275 | E9: 0.0325 | G9: =CHOOSE($C$5,C9,D9,E9)
A10: Exit EV / EBITDA | C10: 11 | D10: 14 | E10: 17 | G10: =CHOOSE($C$5,C10,D10,E10)
A11: Probabilities sum to | C11: =SUM(C8:E8)
A12: What has to be true | C12: FY26 lands at the $3.90B low end of guidance, the Field Systems product swap costs a further 400–500bp of segment ARR growth into 2027, and AI tools cap pricing: revenue growth halves to 4% from FY27 and GAAP operating margin stalls near 19%. | D12: Revenue meets the $3.925B FY26 guide (+9.4%) and growth steps down 0.5–1pt a year to 6% by FY30 as ARR (12% organic) becomes a larger share; mix lifts gross margin 50bp a year and SG&A leverage takes GAAP operating margin from 16.5% to about 24.5%. | E12: The in-house Field Systems product ramps in 2027, AECO ARR holds its 14% pace and T&L is sold: growth runs 9–10% through FY29, gross margin reaches 73.5% and GAAP operating margin passes 28% by FY30.
A14: Scenario outputs | C14: Bear | D14: Base | E14: Bull | F14: Prob.-weighted | G14: Live
A15: Revenue, FY2030E | C15: 4496.1573 | D15: 5167.8141 | E15: 5595.2235 | F15: =SUMPRODUCT($C$8:$E$8,C15:E15) | G15: ='Income Statement'!I7
A16: Revenue CAGR, FY2025A–FY2030E | C16: 0.046200105 | D16: 0.075741286 | E16: 0.092974296 | F16: =SUMPRODUCT($C$8:$E$8,C16:E16) | G16: =('Income Statement'!I7/'Income Statement'!D7)^(1/5)-1
A17: Operating margin, FY2030E | C17: 0.18 | D17: 0.245 | E17: 0.285 | F17: =SUMPRODUCT($C$8:$E$8,C17:E17) | G17: ='Income Statement'!I16
A18: Diluted EPS, FY2026E | C18: 2.0708344 | D18: 2.3666432 | E18: 2.5927856 | F18: =SUMPRODUCT($C$8:$E$8,C18:E18) | G18: ='Income Statement'!E33
A19: Diluted EPS, FY2030E | C19: 3.1565505 | D19: 5.1102555 | E19: 6.516911 | F19: =SUMPRODUCT($C$8:$E$8,C19:E19) | G19: ='Income Statement'!I33
A20: Cumulative free cash flow, 5 years | C20: 4596.9255 | D20: 5948.2109 | E20: 6924.2967 | F20: =SUMPRODUCT($C$8:$E$8,C20:E20) | G20: =SUM('Cash Flow'!E35:I35)
A21: ROIC, FY2030E | C21: 0.10873553 | D21: 0.17287185 | E21: 0.21949129 | F21: =SUMPRODUCT($C$8:$E$8,C21:E21) | G21: =Ratios!I7
A22: Value per share, perpetuity ($) | C22: 35.001949 | D22: 56.368985 | E22: 73.660434 | F22: =SUMPRODUCT($C$8:$E$8,C22:E22) | G22: =DCF!B50
A23: Value per share, exit multiple ($) | C23: 37.334397 | D23: 66.930386 | E23: 96.92293 | F23: =SUMPRODUCT($C$8:$E$8,C23:E23) | G23: =DCF!C50
A24: Value per share, blend ($) | C24: 36.168173 | D24: 61.649686 | E24: 85.291682 | F24: =SUMPRODUCT($C$8:$E$8,C24:E24) | G24: =DCF!C56
A25: Upside / (downside) to current price | C25: -0.36912309 | D25: 0.075347738 | E25: 0.48773211 | F25: =IF(DCF!$C$5=0,0,F24/DCF!$C$5-1) | G25: =DCF!C57
A27: Bear, Base and Bull columns are values captured when the model was built (each scenario calculated in turn). The Live column follows the selector above.

Sheet Assumptions
A1: Assumptions
A2: Yellow cells are inputs. The live row in each block follows the scenario selected on the Scenarios sheet.
C3: Actual | E3: Projected →
A4: Fiscal year | C4: FY2024A | D4: FY2025A | E4: FY2026E | F4: FY2027E | G4: FY2028E | H4: FY2029E | I4: FY2030E
A6: Revenue growth
A7: Live (selected scenario) | D7: ='Income Statement'!D8 | E7: =CHOOSE(Scenarios!$C$5,E8,E9,E10) | F7: =CHOOSE(Scenarios!$C$5,F8,F9,F10) | G7: =CHOOSE(Scenarios!$C$5,G8,G9,G10) | H7: =CHOOSE(Scenarios!$C$5,H8,H9,H10) | I7: =CHOOSE(Scenarios!$C$5,I8,I9,I10)
A8: Bear | E8: 0.087 | F8: 0.04 | G8: 0.04 | H8: 0.035 | I8: 0.03
A9: Base | E9: 0.094 | F9: 0.08 | G9: 0.075 | H9: 0.07 | I9: 0.06
A10: Bull | E10: 0.1 | F10: 0.1 | G10: 0.095 | H10: 0.09 | I10: 0.08
A12: Gross margin
A13: Live (selected scenario) | C13: ='Income Statement'!C11 | D13: ='Income Statement'!D11 | E13: =CHOOSE(Scenarios!$C$5,E14,E15,E16) | F13: =CHOOSE(Scenarios!$C$5,F14,F15,F16) | G13: =CHOOSE(Scenarios!$C$5,G14,G15,G16) | H13: =CHOOSE(Scenarios!$C$5,H14,H15,H16) | I13: =CHOOSE(Scenarios!$C$5,I14,I15,I16)
A14: Bear | E14: 0.695 | F14: 0.695 | G14: 0.695 | H14: 0.695 | I14: 0.695
A15: Base | E15: 0.7 | F15: 0.705 | G15: 0.71 | H15: 0.715 | I15: 0.72
A16: Bull | E16: 0.705 | F16: 0.715 | G16: 0.725 | H16: 0.73 | I16: 0.735
A18: R&D % of revenue
A19: Live (selected scenario) | C19: ='Income Statement'!C12/'Income Statement'!C7 | D19: ='Income Statement'!D12/'Income Statement'!D7 | E19: =CHOOSE(Scenarios!$C$5,E20,E21,E22) | F19: =CHOOSE(Scenarios!$C$5,F20,F21,F22) | G19: =CHOOSE(Scenarios!$C$5,G20,G21,G22) | H19: =CHOOSE(Scenarios!$C$5,H20,H21,H22) | I19: =CHOOSE(Scenarios!$C$5,I20,I21,I22)
A20: Bear | E20: 0.18 | F20: 0.18 | G20: 0.18 | H20: 0.18 | I20: 0.18
A21: Base | E21: 0.175 | F21: 0.175 | G21: 0.175 | H21: 0.175 | I21: 0.175
A22: Bull | E22: 0.17 | F22: 0.17 | G22: 0.165 | H22: 0.165 | I22: 0.165
A24: SG&A % of revenue
A25: Live (selected scenario) | C25: ='Income Statement'!C13/'Income Statement'!C7 | D25: ='Income Statement'!D13/'Income Statement'!D7 | E25: =CHOOSE(Scenarios!$C$5,E26,E27,E28) | F25: =CHOOSE(Scenarios!$C$5,F26,F27,F28) | G25: =CHOOSE(Scenarios!$C$5,G26,G27,G28) | H25: =CHOOSE(Scenarios!$C$5,H26,H27,H28) | I25: =CHOOSE(Scenarios!$C$5,I26,I27,I28)
A26: Bear | E26: 0.315 | F26: 0.315 | G26: 0.31 | H26: 0.31 | I26: 0.31
A27: Base | E27: 0.305 | F27: 0.295 | G27: 0.285 | H27: 0.28 | I27: 0.275
A28: Bull | E28: 0.3 | F28: 0.285 | G28: 0.275 | H28: 0.265 | I28: 0.26
A30: Capex % of revenue
A31: Live (selected scenario) | C31: ='Cash Flow'!C36/'Income Statement'!C7 | D31: ='Cash Flow'!D36/'Income Statement'!D7 | E31: =CHOOSE(Scenarios!$C$5,E32,E33,E34) | F31: =CHOOSE(Scenarios!$C$5,F32,F33,F34) | G31: =CHOOSE(Scenarios!$C$5,G32,G33,G34) | H31: =CHOOSE(Scenarios!$C$5,H32,H33,H34) | I31: =CHOOSE(Scenarios!$C$5,I32,I33,I34)
A32: Bear | E32: 0.009 | F32: 0.009 | G32: 0.009 | H32: 0.009 | I32: 0.009
A33: Base | E33: 0.008 | F33: 0.008 | G33: 0.008 | H33: 0.008 | I33: 0.008
A34: Bull | E34: 0.008 | F34: 0.008 | G34: 0.008 | H34: 0.008 | I34: 0.008
A36: Shared drivers (all scenarios)
A37: Other operating expense % of revenue | E37: 0.035 | F37: 0.03 | G37: 0.028 | H37: 0.026 | I37: 0.025
A38: D&A % of revenue | E38: 0.052 | F38: 0.05 | G38: 0.048 | H38: 0.046 | I38: 0.045
A39: Stock comp % of revenue | E39: 0.04 | F39: 0.04 | G39: 0.04 | H39: 0.04 | I39: 0.04
A40: Tax rate | E40: 0.17 | F40: 0.17 | G40: 0.17 | H40: 0.17 | I40: 0.17
A41: DSO (days of revenue) | E41: 85 | F41: 85 | G41: 85 | H41: 85 | I41: 85
A42: DIO (days of COGS) | E42: 60 | F42: 60 | G42: 60 | H42: 60 | I42: 60
A43: DPO (days of COGS) | E43: 55 | F43: 55 | G43: 55 | H43: 55 | I43: 55
A44: Other current assets % of revenue | E44: 0.094 | F44: 0.094 | G44: 0.094 | H44: 0.094 | I44: 0.094
A45: Other current liabilities % of revenue | E45: 0.372 | F45: 0.372 | G45: 0.372 | H45: 0.372 | I45: 0.372
A46: Interest rate on debt (opening balance) | E46: 0.053 | F46: 0.053 | G46: 0.053 | H46: 0.053 | I46: 0.053
...

Sheet Income Statement
A1: Income Statement
A2: $ millions except per-share data
C3: Actual | E3: Projected →
A4: Fiscal year | C4: FY2024A | D4: FY2025A | E4: FY2026E | F4: FY2027E | G4: FY2028E | H4: FY2029E | I4: FY2030E
A6: Income statement
A7: Revenue | C7: 3683.3 | D7: 3587.3 | E7: =D7*(1+Assumptions!E7) | F7: =E7*(1+Assumptions!F7) | G7: =F7*(1+Assumptions!G7) | H7: =G7*(1+Assumptions!H7) | I7: =H7*(1+Assumptions!I7)
A8: Growth | D8: =D7/C7-1 | E8: =E7/D7-1 | F8: =F7/E7-1 | G8: =G7/F7-1 | H8: =H7/G7-1 | I8: =I7/H7-1
A9: Cost of revenue | C9: 1287 | D9: 1109.4 | E9: =E7*(1-Assumptions!E13) | F9: =F7*(1-Assumptions!F13) | G9: =G7*(1-Assumptions!G13) | H9: =H7*(1-Assumptions!H13) | I9: =I7*(1-Assumptions!I13)
A10: Gross profit | C10: =C7-C9 | D10: =D7-D9 | E10: =E7-E9 | F10: =F7-F9 | G10: =G7-G9 | H10: =H7-H9 | I10: =I7-I9
A11: Gross margin | C11: =C10/C7 | D11: =D10/D7 | E11: =E10/E7 | F11: =F10/F7 | G11: =G10/G7 | H11: =H10/H7 | I11: =I10/I7
A12: Research & development | C12: 662.3 | D12: 630.7 | E12: =E7*Assumptions!E19 | F12: =F7*Assumptions!F19 | G12: =G7*Assumptions!G19 | H12: =H7*Assumptions!H19 | I12: =I7*Assumptions!I19
A13: Selling, general & administrative | C13: 1151.7 | D13: 1129.1 | E13: =E7*Assumptions!E25 | F13: =F7*Assumptions!F25 | G13: =G7*Assumptions!G25 | H13: =H7*Assumptions!H25 | I13: =I7*Assumptions!I25
A14: Other operating expense, net | C14: 121.6 | D14: 126.1 | E14: =E7*Assumptions!E37 | F14: =F7*Assumptions!F37 | G14: =G7*Assumptions!G37 | H14: =H7*Assumptions!H37 | I14: =I7*Assumptions!I37
A15: Operating income (EBIT) | C15: =C10-C12-C13-C14 | D15: =D10-D12-D13-D14 | E15: =E10-E12-E13-E14 | F15: =F10-F12-F13-F14 | G15: =G10-G12-G13-G14 | H15: =H10-H12-H13-H14 | I15: =I10-I12-I13-I14
A16: Operating margin | C16: =C15/C7 | D16: =D15/D7 | E16: =E15/E7 | F16: =F15/F7 | G16: =G15/G7 | H16: =H15/H7 | I16: =I15/I7
A17: Interest expense | C17: 90.7 | D17: 74.4 | E17: ='Balance Sheet'!D20*Assumptions!E46 | F17: ='Balance Sheet'!E20*Assumptions!F46 | G17: ='Balance Sheet'!F20*Assumptions!G46 | H17: ='Balance Sheet'!G20*Assumptions!H46 | I17: ='Balance Sheet'!H20*Assumptions!I46
A18: Interest income & other, net | C18: 1635.9 | D18: -8.2 | E18: =('Balance Sheet'!D7+'Balance Sheet'!D8)*Assumptions!E47 | F18: =('Balance Sheet'!E7+'Balance Sheet'!E8)*Assumptions!F47 | G18: =('Balance Sheet'!F7+'Balance Sheet'!F8)*Assumptions!G47 | H18: =('Balance Sheet'!G7+'Balance Sheet'!G8)*Assumptions!H47 | I18: =('Balance Sheet'!H7+'Balance Sheet'!H8)*Assumptions!I47
A19: Pre-tax income | C19: =C15-C17+C18 | D19: =D15-D17+D18 | E19: =E15-E17+E18 | F19: =F15-F17+F18 | G19: =G15-G17+G18 | H19: =H15-H17+H18 | I19: =I15-I17+I18
A20: Income tax | C20: 501.5 | D20: 85.4 | E20: =MAX(0,E19*Assumptions!E40) | F20: =MAX(0,F19*Assumptions!F40) | G20: =MAX(0,G19*Assumptions!G40) | H20: =MAX(0,H19*Assumptions!H40) | I20: =MAX(0,I19*Assumptions!I40)
A21: Effective tax rate | C21: =IF(C19=0,0,C20/C19) | D21: =IF(D19=0,0,D20/D19) | E21: =IF(E19=0,0,E20/E19) | F21: =IF(F19=0,0,F20/F19) | G21: =IF(G19=0,0,G20/G19) | H21: =IF(H19=0,0,H20/H19) | I21: =IF(I19=0,0,I20/I19)
A22: Minority interest, discontinued ops & other | C22: 0 | D22: 0 | E22: 0 | F22: 0 | G22: 0 | H22: 0 | I22: 0
A23: Net income | C23: =C19-C20+C22 | D23: =D19-D20+D22 | E23: =E19-E20+E22 | F23: =F19-F20+F22 | G23: =G19-G20+G22 | H23: =H19-H20+H22 | I23: =I19-I20+I22
A24: Net margin | C24: =C23/C7 | D24: =D23/D7 | E24: =E23/E7 | F24: =F23/F7 | G24: =G23/G7 | H24: =H23/H7 | I24: =I23/I7
A26: Share count (millions)
A27: Opening diluted shares | E27: =DCF!$C$7 | F27: =E31 | G27: =F31 | H27: =G31 | I27: =H31
A28: Plus: issued for stock comp | E28: =E27*Assumptions!E51 | F28: =F27*Assumptions!F51 | G28: =G27*Assumptions!G51 | H28: =H27*Assumptions!H51 | I28: =I27*Assumptions!I51
A29: Assumed repurchase price ($) | E29: =DCF!$C$5*(1+DCF!$C$19)^(1-0.5) | F29: =DCF!$C$5*(1+DCF!$C$19)^(2-0.5) | G29: =DCF!$C$5*(1+DCF!$C$19)^(3-0.5) | H29: =DCF!$C$5*(1+DCF!$C$19)^(4-0.5) | I29: =DCF!$C$5*(1+DCF!$C$19)^(5-0.5)
A30: Less: shares repurchased | E30: =IF(E29=0,0,'Cash Flow'!E38/E29) | F30: =IF(F29=0,0,'Cash Flow'!F38/F29) | G30: =IF(G29=0,0,'Cash Flow'!G38/G29) | H30: =IF(H29=0,0,'Cash Flow'!H38/H29) | I30: =IF(I29=0,0,'Cash Flow'!I38/I29)
A31: Closing diluted shares | E31: =E27+E28-E30 | F31: =F27+F28-F30 | G31: =G27+G28-G30 | H31: =H27+H28-H30 | I31: =I27+I28-I30
A32: Average diluted shares (for EPS) | C32: 247.02791 | D32: 240.90909 | E32: =AVERAGE(E27,E31) | F32: =AVERAGE(F27,F31) | G32: =AVERAGE(G27,G31) | H32: =AVERAGE(H27,H31) | I32: =AVERAGE(I27,I31)
A33: Diluted EPS ($) | C33: =IF(C32=0,0,C23/C32) | D33: =IF(D32=0,0,D23/D32) | E33: =IF(E32=0,0,E23/E32) | F33: =IF(F32=0,0,F23/F32) | G33: =IF(G32=0,0,G23/G32) | H33: =IF(H32=0,0,H23/H32) | I33: =IF(I32=0,0,I23/I32)
A34: EPS growth | D34: =IF(C33<=0,0,D33/C33-1) | E34: =IF(D33<=0,0,E33/D33-1) | F34: =IF(E33<=0,0,F33/E33-1) | G34: =IF(F33<=0,0,G33/F33-1) | H34: =IF(G33<=0,0,H33/G33-1) | I34: =IF(H33<=0,0,I33/H33-1)
A36: Memo
A37: Depreciation & amortization | C37: 232 | D37: 199.9 | E37: =E7*Assumptions!E38 | F37: =F7*Assumptions!F38 | G37: =G7*Assumptions!G38 | H37: =H7*Assumptions!H38 | I37: =I7*Assumptions!I38
A38: EBITDA | C38: =C15+C37 | D38: =D15+D37 | E38: =E15+E37 | F38: =F15+F37 | G38: =G15+G37 | H38: =H15+H37 | I38: =I15+I37
A39: EBITDA margin | C39: =C38/C7 | D39: =D38/D7 | E39: =E38/E7 | F39: =F38/F7 | G39: =G38/G7 | H39: =H38/H7 | I39: =I38/I7
A40: Stock-based compensation | C40: 158.6 | D40: 146.5 | E40: =E7*Assumptions!E39 | F40: =F7*Assumptions!F39 | G40: =G7*Assumptions!G39 | H40: =H7*Assumptions!H39 | I40: =I7*Assumptions!I39

Sheet Balance Sheet
A1: Balance Sheet
A2: $ millions except per-share data
C3: Actual | E3: Projected →
A4: Fiscal year | C4: FY2024A | D4: FY2025A | E4: FY2026E | F4: FY2027E | G4: FY2028E | H4: FY2029E | I4: FY2030E
A6: Assets
A7: Cash & equivalents | C7: 747.8 | D7: 253.4 | E7: ='Cash Flow'!E32 | F7: ='Cash Flow'!F32 | G7: ='Cash Flow'!G32 | H7: ='Cash Flow'!H32 | I7: ='Cash Flow'!I32
A8: Short-term investments | C8: 0 | D8: 0 | E8: =D8 | F8: =E8 | G8: =F8 | H8: =G8 | I8: =H8
A9: Accounts receivable | C9: 725.8 | D9: 856 | E9: ='Income Statement'!E7*Assumptions!E41/365 | F9: ='Income Statement'!F7*Assumptions!F41/365 | G9: ='Income Statement'!G7*Assumptions!G41/365 | H9: ='Income Statement'!H7*Assumptions!H41/365 | I9: ='Income Statement'!I7*Assumptions!I41/365
A10: Inventory | C10: 194.3 | D10: 186.3 | E10: ='Income Statement'!E9*Assumptions!E42/365 | F10: ='Income Statement'!F9*Assumptions!F42/365 | G10: ='Income Statement'!G9*Assumptions!G42/365 | H10: ='Income Statement'!H9*Assumptions!H42/365 | I10: ='Income Statement'!I9*Assumptions!I42/365
A11: Other current assets | C11: 602.5 | D11: 336.2 | E11: ='Income Statement'!E7*Assumptions!E44 | F11: ='Income Statement'!F7*Assumptions!F44 | G11: ='Income Statement'!G7*Assumptions!G44 | H11: ='Income Statement'!H7*Assumptions!H44 | I11: ='Income Statement'!I7*Assumptions!I44
A12: Total current assets | C12: =SUM(C7:C11) | D12: =SUM(D7:D11) | E12: =SUM(E7:E11) | F12: =SUM(F7:F11) | G12: =SUM(G7:G11) | H12: =SUM(H7:H11) | I12: =SUM(I7:I11)
A13: Property, plant & equipment, net | C13: 188.4 | D13: 185.5 | E13: =D13+'Cash Flow'!E36-'Income Statement'!E37 | F13: =E13+'Cash Flow'!F36-'Income Statement'!F37 | G13: =F13+'Cash Flow'!G36-'Income Statement'!G37 | H13: =G13+'Cash Flow'!H36-'Income Statement'!H37 | I13: =H13+'Cash Flow'!I36-'Income Statement'!I37
A14: Goodwill, intangibles & other non-current | C14: 7029.5 | D14: 7494.6 | E14: =D14 | F14: =E14 | G14: =F14 | H14: =G14 | I14: =H14
A15: Total assets | C15: =C12+C13+C14 | D15: =D12+D13+D14 | E15: =E12+E13+E14 | F15: =F12+F13+F14 | G15: =G12+G13+G14 | H15: =H12+H13+H14 | I15: =I12+I13+I14
A17: Liabilities & equity
A18: Accounts payable | C18: 161.6 | D18: 168.3 | E18: ='Income Statement'!E9*Assumptions!E43/365 | F18: ='Income Statement'!F9*Assumptions!F43/365 | G18: ='Income Statement'!G9*Assumptions!G43/365 | H18: ='Income Statement'!H9*Assumptions!H43/365 | I18: ='Income Statement'!I9*Assumptions!I43/365
A19: Other current liabilities | C19: 1626.4 | D19: 1335.1 | E19: ='Income Statement'!E7*Assumptions!E45 | F19: ='Income Statement'!F7*Assumptions!F45 | G19: ='Income Statement'!G7*Assumptions!G45 | H19: ='Income Statement'!H7*Assumptions!H45 | I19: ='Income Statement'!I7*Assumptions!I45
A20: Total debt (see debt schedule) | C20: 1390.6 | D20: 1392.2 | E20: =E34 | F20: =F34 | G20: =G34 | H20: =H34 | I20: =I34
A21: Other non-current liabilities | C21: 564.4 | D21: 580.2 | E21: =D21 | F21: =E21 | G21: =F21 | H21: =G21 | I21: =H21
A22: Total liabilities | C22: =SUM(C18:C21) | D22: =SUM(D18:D21) | E22: =SUM(E18:E21) | F22: =SUM(F18:F21) | G22: =SUM(G18:G21) | H22: =SUM(H18:H21) | I22: =SUM(I18:I21)
A23: Total equity | C23: 5745.3 | D23: 5836.2 | E23: =D23+'Income Statement'!E23+'Income Statement'!E40-'Cash Flow'!E37-'Cash Flow'!E38 | F23: =E23+'Income Statement'!F23+'Income Statement'!F40-'Cash Flow'!F37-'Cash Flow'!F38 | G23: =F23+'Income Statement'!G23+'Income Statement'!G40-'Cash Flow'!G37-'Cash Flow'!G38 | H23: =G23+'Income Statement'!H23+'Income Statement'!H40-'Cash Flow'!H37-'Cash Flow'!H38 | I23: =H23+'Income Statement'!I23+'Income Statement'!I40-'Cash Flow'!I37-'Cash Flow'!I38
A24: Total liabilities & equity | C24: =C22+C23 | D24: =D22+D23 | E24: =E22+E23 | F24: =F22+F23 | G24: =G22+G23 | H24: =H22+H23 | I24: =I22+I23
A26: Checks
A27: Assets less liabilities & equity (must be 0) | C27: =ROUND(C15-C24,3) | D27: =ROUND(D15-D24,3) | E27: =ROUND(E15-E24,3) | F27: =ROUND(F15-F24,3) | G27: =ROUND(G15-G24,3) | H27: =ROUND(H15-H24,3) | I27: =ROUND(I15-I24,3)
A28: Cash stays positive (1 = yes) | E28: =IF(E7>=0,1,0) | F28: =IF(F7>=0,1,0) | G28: =IF(G7>=0,1,0) | H28: =IF(H7>=0,1,0) | I28: =IF(I7>=0,1,0)
A29: Reported total assets (10-K) | C29: 9488.3 | D29: 9312
A31: Debt schedule
A32: Opening debt | E32: =D20 | F32: =E20 | G32: =F20 | H32: =G20 | I32: =H20
A33: Issuance / (repayment) | E33: =Assumptions!E48 | F33: =Assumptions!F48 | G33: =Assumptions!G48 | H33: =Assumptions!H48 | I33: =Assumptions!I48
A34: Closing debt | E34: =E32+E33 | F34: =F32+F33 | G34: =G32+G33 | H34: =H32+H33 | I34: =I32+I33
A35: Interest rate on opening balance | E35: =Assumptions!E46 | F35: =Assumptions!F46 | G35: =Assumptions!G46 | H35: =Assumptions!H46 | I35: =Assumptions!I46
A37: Memo
A38: Net debt / (net cash) | C38: =C20-C7-C8 | D38: =D20-D7-D8 | E38: =E20-E7-E8 | F38: =F20-F7-F8 | G38: =G20-G7-G8 | H38: =H20-H7-H8 | I38: =I20-I7-I8
A39: Net working capital (ex cash & debt) | C39: =C9+C10+C11-C18-C19 | D39: =D9+D10+D11-D18-D19 | E39: =E9+E10+E11-E18-E19 | F39: =F9+F10+F11-F18-F19 | G39: =G9+G10+G11-G18-G19 | H39: =H9+H10+H11-H18-H19 | I39: =I9+I10+I11-I18-I19
A40: Invested capital (equity + net debt) | C40: =C23+C20-C7-C8 | D40: =D23+D20-D7-D8 | E40: =E23+E20-E7-E8 | F40: =F23+F20-F7-F8 | G40: =G23+G20-G7-G8 | H40: =H23+H20-H7-H8 | I40: =I23+I20-I7-I8

Sheet Cash Flow
A1: Cash Flow
A2: $ millions except per-share data
C3: Actual | E3: Projected →
A4: Fiscal year | C4: FY2024A | D4: FY2025A | E4: FY2026E | F4: FY2027E | G4: FY2028E | H4: FY2029E | I4: FY2030E
A6: Operating activities
A7: Net income | C7: ='Income Statement'!C23 | D7: ='Income Statement'!D23 | E7: ='Income Statement'!E23 | F7: ='Income Statement'!F23 | G7: ='Income Statement'!G23 | H7: ='Income Statement'!H23 | I7: ='Income Statement'!I23
A8: Depreciation & amortization | C8: ='Income Statement'!C37 | D8: ='Income Statement'!D37 | E8: ='Income Statement'!E37 | F8: ='Income Statement'!F37 | G8: ='Income Statement'!G37 | H8: ='Income Statement'!H37 | I8: ='Income Statement'!I37
A9: Stock-based compensation | C9: ='Income Statement'!C40 | D9: ='Income Statement'!D40 | E9: ='Income Statement'!E40 | F9: ='Income Statement'!F40 | G9: ='Income Statement'!G40 | H9: ='Income Statement'!H40 | I9: ='Income Statement'!I40
A10: (Increase) / decrease in receivables | D10: ='Balance Sheet'!C9-'Balance Sheet'!D9 | E10: ='Balance Sheet'!D9-'Balance Sheet'!E9 | F10: ='Balance Sheet'!E9-'Balance Sheet'!F9 | G10: ='Balance Sheet'!F9-'Balance Sheet'!G9 | H10: ='Balance Sheet'!G9-'Balance Sheet'!H9 | I10: ='Balance Sheet'!H9-'Balance Sheet'!I9
A11: (Increase) / decrease in inventory | D11: ='Balance Sheet'!C10-'Balance Sheet'!D10 | E11: ='Balance Sheet'!D10-'Balance Sheet'!E10 | F11: ='Balance Sheet'!E10-'Balance Sheet'!F10 | G11: ='Balance Sheet'!F10-'Balance Sheet'!G10 | H11: ='Balance Sheet'!G10-'Balance Sheet'!H10 | I11: ='Balance Sheet'!H10-'Balance Sheet'!I10
A12: (Increase) / decrease in other current assets | D12: ='Balance Sheet'!C11-'Balance Sheet'!D11 | E12: ='Balance Sheet'!D11-'Balance Sheet'!E11 | F12: ='Balance Sheet'!E11-'Balance Sheet'!F11 | G12: ='Balance Sheet'!F11-'Balance Sheet'!G11 | H12: ='Balance Sheet'!G11-'Balance Sheet'!H11 | I12: ='Balance Sheet'!H11-'Balance Sheet'!I11
A13: Increase / (decrease) in payables | D13: ='Balance Sheet'!D18-'Balance Sheet'!C18 | E13: ='Balance Sheet'!E18-'Balance Sheet'!D18 | F13: ='Balance Sheet'!F18-'Balance Sheet'!E18 | G13: ='Balance Sheet'!G18-'Balance Sheet'!F18 | H13: ='Balance Sheet'!H18-'Balance Sheet'!G18 | I13: ='Balance Sheet'!I18-'Balance Sheet'!H18
A14: Increase / (decrease) in other current liabilities | D14: ='Balance Sheet'!D19-'Balance Sheet'!C19 | E14: ='Balance Sheet'!E19-'Balance Sheet'!D19 | F14: ='Balance Sheet'!F19-'Balance Sheet'!E19 | G14: ='Balance Sheet'!G19-'Balance Sheet'!F19 | H14: ='Balance Sheet'!H19-'Balance Sheet'!G19 | I14: ='Balance Sheet'!I19-'Balance Sheet'!H19
A15: Other operating items (reported less above) | C15: =531.4-SUM(C7:C14) | D15: =386.0-SUM(D7:D14) | E15: 0 | F15: 0 | G15: 0 | H15: 0 | I15: 0
A16: Cash from operations | C16: =SUM(C7:C15) | D16: =SUM(D7:D15) | E16: =SUM(E7:E15) | F16: =SUM(F7:F15) | G16: =SUM(G7:G15) | H16: =SUM(H7:H15) | I16: =SUM(I7:I15)
A18: Investing activities
A19: Capital expenditures | C19: -33.6 | D19: -25 | E19: =-E36 | F19: =-F36 | G19: =-G36 | H19: =-H36 | I19: =-I36
A20: Acquisitions, investments & other | C20: 1894.7 | D20: 0 | E20: 0 | F20: 0 | G20: 0 | H20: 0 | I20: 0
A21: Cash from investing | C21: =C19+C20 | D21: =D19+D20 | E21: =E19+E20 | F21: =F19+F20 | G21: =G19+G20 | H21: =H19+H20 | I21: =I19+I20
A23: Financing activities
A24: Net debt issuance / (repayment) | E24: ='Balance Sheet'!E33 | F24: ='Balance Sheet'!F33 | G24: ='Balance Sheet'!G33 | H24: ='Balance Sheet'!H33 | I24: ='Balance Sheet'!I33
A25: Dividends paid | C25: 0 | D25: 0 | E25: =-E37 | F25: =-F37 | G25: =-G37 | H25: =-H37 | I25: =-I37
A26: Share repurchases | C26: -175 | D26: -875.5 | E26: =-E38 | F26: =-F38 | G26: =-G38 | H26: =-H38 | I26: =-I38
A27: Debt & other financing (reported less above) | C27: -1708.6 | D27: 20.1 | E27: 0 | F27: 0 | G27: 0 | H27: 0 | I27: 0
A28: Cash from financing | C28: =SUM(C24:C27) | D28: =SUM(D24:D27) | E28: =SUM(E24:E27) | F28: =SUM(F24:F27) | G28: =SUM(G24:G27) | H28: =SUM(H24:H27) | I28: =SUM(I24:I27)
A30: Net change in cash | C30: =C16+C21+C28 | D30: =D16+D21+D28 | E30: =E16+E21+E28 | F30: =F16+F21+F28 | G30: =G16+G21+G28 | H30: =H16+H21+H28 | I30: =I16+I21+I28
A31: Beginning cash | E31: ='Balance Sheet'!D7 | F31: ='Balance Sheet'!E7 | G31: ='Balance Sheet'!F7 | H31: ='Balance Sheet'!G7 | I31: ='Balance Sheet'!H7
A32: Ending cash | E32: =E31+E30 | F32: =F31+F30 | G32: =G31+G30 | H32: =H31+H30 | I32: =I31+I30
A34: Memo
A35: Free cash flow (CFO less capex) | C35: =C16+C19 | D35: =D16+D19 | E35: =E16+E19 | F35: =F16+F19 | G35: =G16+G19 | H35: =H16+H19 | I35: =I16+I19
A36: Capex | C36: 33.6 | D36: 25 | E36: ='Income Statement'!E7*Assumptions!E31 | F36: ='Income Statement'!F7*Assumptions!F31 | G36: ='Income Statement'!G7*Assumptions!G31 | H36: ='Income Statement'!H7*Assumptions!H31 | I36: ='Income Statement'!I7*Assumptions!I31
A37: Dividends | C37: 0 | D37: 0 | E37: =MAX(0,'Income Statement'!E23*Assumptions!E49) | F37: =MAX(0,'Income Statement'!F23*Assumptions!F49) | G37: =MAX(0,'Income Statement'!G23*Assumptions!G49) | H37: =MAX(0,'Income Statement'!H23*Assumptions!H49) | I37: =MAX(0,'Income Statement'!I23*Assumptions!I49)
A38: Buybacks | C38: 175 | D38: 875.5 | E38: =Assumptions!E50 | F38: =Assumptions!F50 | G38: =Assumptions!G50 | H38: =Assumptions!H50 | I38: =Assumptions!I50

Sheet Ratios
A1: Ratios
A2: Returns, cash conversion, leverage and efficiency
C3: Actual | E3: Projected →
A4: Fiscal year | C4: FY2024A | D4: FY2025A | E4: FY2026E | F4: FY2027E | G4: FY2028E | H4: FY2029E | I4: FY2030E
A6: Returns
A7: Return on invested capital (after tax) | C7: =IF('Balance Sheet'!C40<=0,0,'Income Statement'!C15*(1-'Income Statement'!C21)/'Balance Sheet'!C40) | D7: =IF(AVERAGE('Balance Sheet'!D40,'Balance Sheet'!C40)<=0,0,'Income Statement'!D15*(1-'Income Statement'!D21)/AVERAGE('Balance Sheet'!D40,'Balance Sheet'!C40)) | E7: =IF(AVERAGE('Balance Sheet'!E40,'Balance Sheet'!D40)<=0,0,'Income Statement'!E15*(1-'Income Statement'!E21)/AVERAGE('Balance Sheet'!E40,'Balance Sheet'!D40)) | F7: =IF(AVERAGE('Balance Sheet'!F40,'Balance Sheet'!E40)<=0,0,'Income Statement'!F15*(1-'Income Statement'!F21)/AVERAGE('Balance Sheet'!F40,'Balance Sheet'!E40)) | G7: =IF(AVERAGE('Balance Sheet'!G40,'Balance Sheet'!F40)<=0,0,'Income Statement'!G15*(1-'Income Statement'!G21)/AVERAGE('Balance Sheet'!G40,'Balance Sheet'!F40)) | H7: =IF(AVERAGE('Balance Sheet'!H40,'Balance Sheet'!G40)<=0,0,'Income Statement'!H15*(1-'Income Statement'!H21)/AVERAGE('Balance Sheet'!H40,'Balance Sheet'!G40)) | I7: =IF(AVERAGE('Balance Sheet'!I40,'Balance Sheet'!H40)<=0,0,'Income Statement'!I15*(1-'Income Statement'!I21)/AVERAGE('Balance Sheet'!I40,'Balance Sheet'!H40))
A8: Return on equity | C8: =IF('Balance Sheet'!C23<=0,0,'Income Statement'!C23/'Balance Sheet'!C23) | D8: =IF('Balance Sheet'!D23<=0,0,'Income Statement'!D23/'Balance Sheet'!D23) | E8: =IF('Balance Sheet'!E23<=0,0,'Income Statement'!E23/'Balance Sheet'!E23) | F8: =IF('Balance Sheet'!F23<=0,0,'Income Statement'!F23/'Balance Sheet'!F23) | G8: =IF('Balance Sheet'!G23<=0,0,'Income Statement'!G23/'Balance Sheet'!G23) | H8: =IF('Balance Sheet'!H23<=0,0,'Income Statement'!H23/'Balance Sheet'!H23) | I8: =IF('Balance Sheet'!I23<=0,0,'Income Statement'!I23/'Balance Sheet'!I23)
A10: Cash generation
A11: Free cash flow margin | C11: ='Cash Flow'!C35/'Income Statement'!C7 | D11: ='Cash Flow'!D35/'Income Statement'!D7 | E11: ='Cash Flow'!E35/'Income Statement'!E7 | F11: ='Cash Flow'!F35/'Income Statement'!F7 | G11: ='Cash Flow'!G35/'Income Statement'!G7 | H11: ='Cash Flow'!H35/'Income Statement'!H7 | I11: ='Cash Flow'!I35/'Income Statement'!I7
A12: FCF conversion (FCF / net income) | C12: =IF('Income Statement'!C23<=0,0,'Cash Flow'!C35/'Income Statement'!C23) | D12: =IF('Income Statement'!D23<=0,0,'Cash Flow'!D35/'Income Statement'!D23) | E12: =IF('Income Statement'!E23<=0,0,'Cash Flow'!E35/'Income Statement'!E23) | F12: =IF('Income Statement'!F23<=0,0,'Cash Flow'!F35/'Income Statement'!F23) | G12: =IF('Income Statement'!G23<=0,0,'Cash Flow'!G35/'Income Statement'!G23) | H12: =IF('Income Statement'!H23<=0,0,'Cash Flow'!H35/'Income Statement'!H23) | I12: =IF('Income Statement'!I23<=0,0,'Cash Flow'!I35/'Income Statement'!I23)
A13: Free cash flow per share ($) | C13: =IF('Income Statement'!C32=0,0,'Cash Flow'!C35/'Income Statement'!C32) | D13: =IF('Income Statement'!D32=0,0,'Cash Flow'!D35/'Income Statement'!D32) | E13: =IF('Income Statement'!E32=0,0,'Cash Flow'!E35/'Income Statement'!E32) | F13: =IF('Income Statement'!F32=0,0,'Cash Flow'!F35/'Income Statement'!F32) | G13: =IF('Income Statement'!G32=0,0,'Cash Flow'!G35/'Income Statement'!G32) | H13: =IF('Income Statement'!H32=0,0,'Cash Flow'!H35/'Income Statement'!H32) | I13: =IF('Income Statement'!I32=0,0,'Cash Flow'!I35/'Income Statement'!I32)
A14: Capex / D&A | C14: =IF('Income Statement'!C37=0,0,'Cash Flow'!C36/'Income Statement'!C37) | D14: =IF('Income Statement'!D37=0,0,'Cash Flow'!D36/'Income Statement'!D37) | E14: =IF('Income Statement'!E37=0,0,'Cash Flow'!E36/'Income Statement'!E37) | F14: =IF('Income Statement'!F37=0,0,'Cash Flow'!F36/'Income Statement'!F37) | G14: =IF('Income Statement'!G37=0,0,'Cash Flow'!G36/'Income Statement'!G37) | H14: =IF('Income Statement'!H37=0,0,'Cash Flow'!H36/'Income Statement'!H37) | I14: =IF('Income Statement'!I37=0,0,'Cash Flow'!I36/'Income Statement'!I37)
A15: Stock comp % of revenue | C15: ='Income Statement'!C40/'Income Statement'!C7 | D15: ='Income Statement'!D40/'Income Statement'!D7 | E15: ='Income Statement'!E40/'Income Statement'!E7 | F15: ='Income Statement'!F40/'Income Statement'!F7 | G15: ='Income Statement'!G40/'Income Statement'!G7 | H15: ='Income Statement'!H40/'Income Statement'!H7 | I15: ='Income Statement'!I40/'Income Statement'!I7
A16: Shareholder returns % of FCF | C16: =IF('Cash Flow'!C35<=0,0,('Cash Flow'!C37+'Cash Flow'!C38)/'Cash Flow'!C35) | D16: =IF('Cash Flow'!D35<=0,0,('Cash Flow'!D37+'Cash Flow'!D38)/'Cash Flow'!D35) | E16: =IF('Cash Flow'!E35<=0,0,('Cash Flow'!E37+'Cash Flow'!E38)/'Cash Flow'!E35) | F16: =IF('Cash Flow'!F35<=0,0,('Cash Flow'!F37+'Cash Flow'!F38)/'Cash Flow'!F35) | G16: =IF('Cash Flow'!G35<=0,0,('Cash Flow'!G37+'Cash Flow'!G38)/'Cash Flow'!G35) | H16: =IF('Cash Flow'!H35<=0,0,('Cash Flow'!H37+'Cash Flow'!H38)/'Cash Flow'!H35) | I16: =IF('Cash Flow'!I35<=0,0,('Cash Flow'!I37+'Cash Flow'!I38)/'Cash Flow'!I35)
A18: Leverage
A19: Net debt / EBITDA | C19: =IF('Income Statement'!C38<=0,0,'Balance Sheet'!C38/'Income Statement'!C38) | D19: =IF('Income Statement'!D38<=0,0,'Balance Sheet'!D38/'Income Statement'!D38) | E19: =IF('Income Statement'!E38<=0,0,'Balance Sheet'!E38/'Income Statement'!E38) | F19: =IF('Income Statement'!F38<=0,0,'Balance Sheet'!F38/'Income Statement'!F38) | G19: =IF('Income Statement'!G38<=0,0,'Balance Sheet'!G38/'Income Statement'!G38) | H19: =IF('Income Statement'!H38<=0,0,'Balance Sheet'!H38/'Income Statement'!H38) | I19: =IF('Income Statement'!I38<=0,0,'Balance Sheet'!I38/'Income Statement'!I38)
A20: EBITDA / interest expense | C20: =IF('Income Statement'!C17<=0,0,'Income Statement'!C38/'Income Statement'!C17) | D20: =IF('Income Statement'!D17<=0,0,'Income Statement'!D38/'Income Statement'!D17) | E20: =IF('Income Statement'!E17<=0,0,'Income Statement'!E38/'Income Statement'!E17) | F20: =IF('Income Statement'!F17<=0,0,'Income Statement'!F38/'Income Statement'!F17) | G20: =IF('Income Statement'!G17<=0,0,'Income Statement'!G38/'Income Statement'!G17) | H20: =IF('Income Statement'!H17<=0,0,'Income Statement'!H38/'Income Statement'!H17) | I20: =IF('Income Statement'!I17<=0,0,'Income Statement'!I38/'Income Statement'!I17)
A22: Working capital
A23: Days sales outstanding | C23: ='Balance Sheet'!C9/'Income Statement'!C7*365 | D23: ='Balance Sheet'!D9/'Income Statement'!D7*365 | E23: ='Balance Sheet'!E9/'Income Statement'!E7*365 | F23: ='Balance Sheet'!F9/'Income Statement'!F7*365 | G23: ='Balance Sheet'!G9/'Income Statement'!G7*365 | H23: ='Balance Sheet'!H9/'Income Statement'!H7*365 | I23: ='Balance Sheet'!I9/'Income Statement'!I7*365
A24: Days inventory | C24: =IF('Income Statement'!C9=0,0,'Balance Sheet'!C10/'Income Statement'!C9*365) | D24: =IF('Income Statement'!D9=0,0,'Balance Sheet'!D10/'Income Statement'!D9*365) | E24: =IF('Income Statement'!E9=0,0,'Balance Sheet'!E10/'Income Statement'!E9*365) | F24: =IF('Income Statement'!F9=0,0,'Balance Sheet'!F10/'Income Statement'!F9*365) | G24: =IF('Income Statement'!G9=0,0,'Balance Sheet'!G10/'Income Statement'!G9*365) | H24: =IF('Income Statement'!H9=0,0,'Balance Sheet'!H10/'Income Statement'!H9*365) | I24: =IF('Income Statement'!I9=0,0,'Balance Sheet'!I10/'Income Statement'!I9*365)
A25: Days payables | C25: =IF('Income Statement'!C9=0,0,'Balance Sheet'!C18/'Income Statement'!C9*365) | D25: =IF('Income Statement'!D9=0,0,'Balance Sheet'!D18/'Income Statement'!D9*365) | E25: =IF('Income Statement'!E9=0,0,'Balance Sheet'!E18/'Income Statement'!E9*365) | F25: =IF('Income Statement'!F9=0,0,'Balance Sheet'!F18/'Income Statement'!F9*365) | G25: =IF('Income Statement'!G9=0,0,'Balance Sheet'!G18/'Income Statement'!G9*365) | H25: =IF('Income Statement'!H9=0,0,'Balance Sheet'!H18/'Income Statement'!H9*365) | I25: =IF('Income Statement'!I9=0,0,'Balance Sheet'!I18/'Income Statement'!I9*365)
A26: Net working capital % of revenue | C26: ='Balance Sheet'!C39/'Income Statement'!C7 | D26: ='Balance Sheet'!D39/'Income Statement'!D7 | E26: ='Balance Sheet'!E39/'Income Statement'!E7 | F26: ='Balance Sheet'!F39/'Income Statement'!F7 | G26: ='Balance Sheet'!G39/'Income Statement'!G7 | H26: ='Balance Sheet'!H39/'Income Statement'!H7 | I26: ='Balance Sheet'!I39/'Income Statement'!I7

Sheet DCF
A1: Discounted cash flow
A2: $ millions except per-share. Yellow = input; green = link to another sheet.
A4: Market data & inputs
A5: Share price ($) | C5: 57.33
A6: Price as of | C6: 2026-09-21
A7: Diluted shares (m) | C7: 234
A8: Risk-free rate (10-year Treasury) | C8: 0.0493
A9: Equity risk premium | C9: 0.05
A10: Beta | C10: 1.21
A11: Pre-tax cost of debt | C11: 0.053
A12: Tax rate (first projection year) | C12: =Assumptions!E40
A13: Terminal growth (selected scenario) | C13: =Scenarios!$G$9
A14: Exit EV / EBITDA (selected scenario) | C14: =Scenarios!$G$10
A15: Mid-year convention (1 = on, 0 = off) | C15: 1
A17: Cost of capital
A18: Market capitalization | C18: =C5*C7
A19: Cost of equity (CAPM) | C19: =C8+C10*C9
A20: After-tax cost of debt | C20: =C11*(1-C12)
A21: Gross debt, latest actual | C21: ='Balance Sheet'!D20
A22: Net debt / (net cash), latest actual | C22: ='Balance Sheet'!D38
A23: Equity weight | C23: =IF(C18+C21=0,1,C18/(C18+C21))
A24: WACC | C24: =C23*C19+(1-C23)*C20
A26: Unlevered free cash flow
C27: FY2026E | D27: FY2027E | E27: FY2028E | F27: FY2029E | G27: FY2030E
A28: Revenue | C28: ='Income Statement'!E7 | D28: ='Income Statement'!F7 | E28: ='Income Statement'!G7 | F28: ='Income Statement'!H7 | G28: ='Income Statement'!I7
A29: EBITDA | C29: ='Income Statement'!E38 | D29: ='Income Statement'!F38 | E29: ='Income Statement'!G38 | F29: ='Income Statement'!H38 | G29: ='Income Statement'!I38
A30: EBIT | C30: ='Income Statement'!E15 | D30: ='Income Statement'!F15 | E30: ='Income Statement'!G15 | F30: ='Income Statement'!H15 | G30: ='Income Statement'!I15
A31: Less: taxes on EBIT | C31: =-C30*Assumptions!E40 | D31: =-D30*Assumptions!F40 | E31: =-E30*Assumptions!G40 | F31: =-F30*Assumptions!H40 | G31: =-G30*Assumptions!I40
A32: NOPAT | C32: =C30+C31 | D32: =D30+D31 | E32: =E30+E31 | F32: =F30+F31 | G32: =G30+G31
A33: Plus: D&A | C33: ='Income Statement'!E37 | D33: ='Income Statement'!F37 | E33: ='Income Statement'!G37 | F33: ='Income Statement'!H37 | G33: ='Income Statement'!I37
A34: Less: capex | C34: ='Cash Flow'!E19 | D34: ='Cash Flow'!F19 | E34: ='Cash Flow'!G19 | F34: ='Cash Flow'!H19 | G34: ='Cash Flow'!I19
A35: Less: increase in net working capital | C35: ='Balance Sheet'!D39-'Balance Sheet'!E39 | D35: ='Balance Sheet'!E39-'Balance Sheet'!F39 | E35: ='Balance Sheet'!F39-'Balance Sheet'!G39 | F35: ='Balance Sheet'!G39-'Balance Sheet'!H39 | G35: ='Balance Sheet'!H39-'Balance Sheet'!I39
A36: Unlevered free cash flow | C36: =SUM(C32:C35) | D36: =SUM(D32:D35) | E36: =SUM(E32:E35) | F36: =SUM(F32:F35) | G36: =SUM(G32:G35)
A37: Discount period (years) | C37: =1-0.5*$C$15 | D37: =2-0.5*$C$15 | E37: =3-0.5*$C$15 | F37: =4-0.5*$C$15 | G37: =5-0.5*$C$15
A38: Discount factor | C38: =1/(1+$C$24)^C37 | D38: =1/(1+$C$24)^D37 | E38: =1/(1+$C$24)^E37 | F38: =1/(1+$C$24)^F37 | G38: =1/(1+$C$24)^G37
A39: Present value of UFCF | C39: =C36*C38 | D39: =D36*D38 | E39: =E36*E38 | F39: =F36*F38 | G39: =G36*G38
A40: Stock comp is treated as a real cost: it is not added back to free cash flow.
A42: Valuation
B43: Perpetuity | C43: Exit multiple
A44: Sum of PV of UFCF | B44: =SUM(C39:G39) | C44: =SUM(C39:G39)
...

Sheet Data
A1: Source data
A2: As reported in 10-K XBRL, USD (shares in units). Source: Trimble 10-K FY2024 and FY2025 and Q4 earnings releases, collected via web search (test run; SEC API blocked in this environment) · fetched 2026-09-23
A4: Field | B4: XBRL tag (latest year) | C4: 2025-01-03 | D4: 2026-01-02
A5: revenue | B5: release/10-K via web search | C5: 3683300000 | D5: 3587300000
A6: cogs | B6: release/10-K via web search | C6: 1287000000 | D6: 1109400000
A7: gross_profit | B7: release/10-K via web search | C7: 2396300000 | D7: 2477900000
A8: rnd | B8: release/10-K via web search | C8: 662300000 | D8: 630700000
A9: sga | B9: release/10-K via web search | C9: 1151700000 | D9: 1129100000
A10: ebit | B10: release/10-K via web search | C10: 460700000 | D10: 592000000
A11: interest_expense | B11: release/10-K via web search | C11: 90700000 | D11: 74400000
A12: pretax | B12: release/10-K via web search | C12: 2005900000 | D12: 509400000
A13: tax | B13: release/10-K via web search | C13: 501500000 | D13: 85400000
A14: net_income | B14: release/10-K via web search | C14: 1504400000 | D14: 424000000
A15: diluted_shares | B15: derived: net income / diluted EPS | C15: 2.4702791e+08 | D15: 2.4090909e+08
A16: cfo | B16: release/10-K via web search | C16: 531400000 | D16: 386000000
... A37: liabilities_and_equity | B37: release/10-K via web search | C37: 9488300000 | D37: 9312000000
